Workbook

Sheet КАЛЬКУЛЯТОР
A1: КОД | B1: КОЛ-ВО | C1: СКИДКА | D1: НАИМЕНОВАНИЕ | E1: ББ | F1: ОП | G1: ПЦ
D2: С У М М А | E2: =SUM(E3:E900) -> 0 | F2: =SUM(F3:F900) -> 0 | G2: =SUM(G3:G900) -> 0
C3: =IF(A3=""," ",VLOOKUP(A3,'01.01.2026 - 24.01.2026'!A:H,2,FALSE)) | D3: =IF(A3=""," ",VLOOKUP(A3,'01.01.2026 - 24.01.2026'!A:H,5,FALSE)) | E3: =IF(A3=""," ",B3*VLOOKUP(A3,'01.01.2026 - 24.01.2026'!A:H,6,FALSE)) | F3: =IF(A3=""," ",B3*VLOOKUP(A3,'01.01.2026 - 24.01.2026'!A:H,7,FALSE)) | G3: =IF(A3=""," ",B3*VLOOKUP(A3,'01.01.2026 - 24.01.2026'!A:H,8,FALSE))
C4: =IF(A4=""," ",VLOOKUP(A4,'01.01.2026 - 24.01.2026'!A:H,2,FALSE)) | D4: =IF(A4=""," ",VLOOKUP(A4,'01.01.2026 - 24.01.2026'!A:H,5,FALSE)) | E4: =IF(A4=""," ",B4*VLOOKUP(A4,'01.01.2026 - 24.01.2026'!A:H,6,FALSE)) | F4: =IF(A4=""," ",B4*VLOOKUP(A4,'01.01.2026 - 24.01.2026'!A:H,7,FALSE)) | G4: =IF(A4=""," ",B4*VLOOKUP(A4,'01.01.2026 - 24.01.2026'!A:H,8,FALSE))
C5: =IF(A5=""," ",VLOOKUP(A5,'01.01.2026 - 24.01.2026'!A:H,2,FALSE)) | D5: =IF(A5=""," ",VLOOKUP(A5,'01.01.2026 - 24.01.2026'!A:H,5,FALSE)) | E5: =IF(A5=""," ",B5*VLOOKUP(A5,'01.01.2026 - 24.01.2026'!A:H,6,FALSE)) | F5: =IF(A5=""," ",B5*VLOOKUP(A5,'01.01.2026 - 24.01.2026'!A:H,7,FALSE)) | G5: =IF(A5=""," ",B5*VLOOKUP(A5,'01.01.2026 - 24.01.2026'!A:H,8,FALSE))
C6: =IF(A6=""," ",VLOOKUP(A6,'01.01.2026 - 24.01.2026'!A:H,2,FALSE)) | D6: =IF(A6=""," ",VLOOKUP(A6,'01.01.2026 - 24.01.2026'!A:H,5,FALSE)) | E6: =IF(A6=""," ",B6*VLOOKUP(A6,'01.01.2026 - 24.01.2026'!A:H,6,FALSE)) | F6: =IF(A6=""," ",B6*VLOOKUP(A6,'01.01.2026 - 24.01.2026'!A:H,7,FALSE)) | G6: =IF(A6=""," ",B6*VLOOKUP(A6,'01.01.2026 - 24.01.2026'!A:H,8,FALSE))
C7: =IF(A7=""," ",VLOOKUP(A7,'01.01.2026 - 24.01.2026'!A:H,2,FALSE)) | D7: =IF(A7=""," ",VLOOKUP(A7,'01.01.2026 - 24.01.2026'!A:H,5,FALSE)) | E7: =IF(A7=""," ",B7*VLOOKUP(A7,'01.01.2026 - 24.01.2026'!A:H,6,FALSE)) | F7: =IF(A7=""," ",B7*VLOOKUP(A7,'01.01.2026 - 24.01.2026'!A:H,7,FALSE)) | G7: =IF(A7=""," ",B7*VLOOKUP(A7,'01.01.2026 - 24.01.2026'!A:H,8,FALSE))
C8: =IF(A8=""," ",VLOOKUP(A8,'01.01.2026 - 24.01.2026'!A:H,2,FALSE)) | D8: =IF(A8=""," ",VLOOKUP(A8,'01.01.2026 - 24.01.2026'!A:H,5,FALSE)) | E8: =IF(A8=""," ",B8*VLOOKUP(A8,'01.01.2026 - 24.01.2026'!A:H,6,FALSE)) | F8: =IF(A8=""," ",B8*VLOOKUP(A8,'01.01.2026 - 24.01.2026'!A:H,7,FALSE)) | G8: =IF(A8=""," ",B8*VLOOKUP(A8,'01.01.2026 - 24.01.2026'!A:H,8,FALSE))
C9: =IF(A9=""," ",VLOOKUP(A9,'01.01.2026 - 24.01.2026'!A:H,2,FALSE)) | D9: =IF(A9=""," ",VLOOKUP(A9,'01.01.2026 - 24.01.2026'!A:H,5,FALSE)) | E9: =IF(A9=""," ",B9*VLOOKUP(A9,'01.01.2026 - 24.01.2026'!A:H,6,FALSE)) | F9: =IF(A9=""," ",B9*VLOOKUP(A9,'01.01.2026 - 24.01.2026'!A:H,7,FALSE)) | G9: =IF(A9=""," ",B9*VLOOKUP(A9,'01.01.2026 - 24.01.2026'!A:H,8,FALSE))
C10: =IF(A10=""," ",VLOOKUP(A10,'01.01.2026 - 24.01.2026'!A:H,2,FALSE)) | D10: =IF(A10=""," ",VLOOKUP(A10,'01.01.2026 - 24.01.2026'!A:H,5,FALSE)) | E10: =IF(A10=""," ",B10*VLOOKUP(A10,'01.01.2026 - 24.01.2026'!A:H,6,FALSE)) | F10: =IF(A10=""," ",B10*VLOOKUP(A10,'01.01.2026 - 24.01.2026'!A:H,7,FALSE)) | G10: =IF(A10=""," ",B10*VLOOKUP(A10,'01.01.2026 - 24.01.2026'!A:H,8,FALSE))
C11: =IF(A11=""," ",VLOOKUP(A11,'01.01.2026 - 24.01.2026'!A:H,2,FALSE)) | D11: =IF(A11=""," ",VLOOKUP(A11,'01.01.2026 - 24.01.2026'!A:H,5,FALSE)) | E11: =IF(A11=""," ",B11*VLOOKUP(A11,'01.01.2026 - 24.01.2026'!A:H,6,FALSE)) | F11: =IF(A11=""," ",B11*VLOOKUP(A11,'01.01.2026 - 24.01.2026'!A:H,7,FALSE)) | G11: =IF(A11=""," ",B11*VLOOKUP(A11,'01.01.2026 - 24.01.2026'!A:H,8,FALSE))
C12: =IF(A12=""," ",VLOOKUP(A12,'01.01.2026 - 24.01.2026'!A:H,2,FALSE)) | D12: =IF(A12=""," ",VLOOKUP(A12,'01.01.2026 - 24.01.2026'!A:H,5,FALSE)) | E12: =IF(A12=""," ",B12*VLOOKUP(A12,'01.01.2026 - 24.01.2026'!A:H,6,FALSE)) | F12: =IF(A12=""," ",B12*VLOOKUP(A12,'01.01.2026 - 24.01.2026'!A:H,7,FALSE)) | G12: =IF(A12=""," ",B12*VLOOKUP(A12,'01.01.2026 - 24.01.2026'!A:H,8,FALSE))
C13: =IF(A13=""," ",VLOOKUP(A13,'01.01.2026 - 24.01.2026'!A:H,2,FALSE)) | D13: =IF(A13=""," ",VLOOKUP(A13,'01.01.2026 - 24.01.2026'!A:H,5,FALSE)) | E13: =IF(A13=""," ",B13*VLOOKUP(A13,'01.01.2026 - 24.01.2026'!A:H,6,FALSE)) | F13: =IF(A13=""," ",B13*VLOOKUP(A13,'01.01.2026 - 24.01.2026'!A:H,7,FALSE)) | G13: =IF(A13=""," ",B13*VLOOKUP(A13,'01.01.2026 - 24.01.2026'!A:H,8,FALSE))
C14: =IF(A14=""," ",VLOOKUP(A14,'01.01.2026 - 24.01.2026'!A:H,2,FALSE)) | D14: =IF(A14=""," ",VLOOKUP(A14,'01.01.2026 - 24.01.2026'!A:H,5,FALSE)) | E14: =IF(A14=""," ",B14*VLOOKUP(A14,'01.01.2026 - 24.01.2026'!A:H,6,FALSE)) | F14: =IF(A14=""," ",B14*VLOOKUP(A14,'01.01.2026 - 24.01.2026'!A:H,7,FALSE)) | G14: =IF(A14=""," ",B14*VLOOKUP(A14,'01.01.2026 - 24.01.2026'!A:H,8,FALSE))
... C876: =IF(A876=""," ",VLOOKUP(A876,'01.01.2026 - 24.01.2026'!A:H,2,FALSE)) | D876: =IF(A876=""," ",VLOOKUP(A876,'01.01.2026 - 24.01.2026'!A:H,5,FALSE)) | E876: =IF(A876=""," ",B876*VLOOKUP(A876,'01.01.2026 - 24.01.2026'!A:H,6,FALSE)) | F876: =IF(A876=""," ",B876*VLOOKUP(A876,'01.01.2026 - 24.01.2026'!A:H,7,FALSE)) | G876: =IF(A876=""," ",B876*VLOOKUP(A876,'01.01.2026 - 24.01.2026'!A:H,8,FALSE))

Sheet 01.01.2026 - 24.01.2026
A1: КОД | B1: СКИДКА | C1: СТР. | D1: АКЦИЯ | E1: НАИМЕНОВАНИЕ | F1: ББ | G1: ОП | H1: ПЦ
A2: НОВИНКИ
A3: 46897 | B3: 0.57096774 | C3: 25 | E3: ВОДОСТОЙКАЯ ТУШЬ ДЛЯ РЕСНИЦ С ЭФФЕКТОМ ОШЕЛОМИТЕЛЬНОГО ОБЪЁМА THE ONE - ЧЁРНЫЙ | F3: 4 | G3: 249 | H3: 399
A4: 48552 | B4: 0.26755853 | C4: 132 | E4: ЧЕХОЛ ДЛЯ МЫЛА | F4: 2 | G4: 68 | H4: 219
A5: 48915 | C5: 120 | E5: ПОЛОТЕНЦЕ-ТЮРБАН ДЛЯ ВОЛОС | F5: 9 | G5: 281 | H5: 899
A6: 48918 | C6: 52 | E6: КРИОМАССАЖЁР ДЛЯ ЛИЦА | F6: 9 | G6: 281 | H6: 899
A7: КАТАЛОГ
E8: WELLOSOPHY
A9: 29699 | C9: 68 | E9: КОМПЛЕКС «МУЛЬТИВИТАМИНЫ И МИНЕРАЛЫ» ДЛЯ ДЕТЕЙ | F9: 23 | G9: 1531 | H9: 2450
A10: 37285 | C10: 65 | E10: СУХАЯ СМЕСЬ ДЛЯ КОКТЕЙЛЯ NATURAL BALANCE - КЛУБНИЧНЫЙ ВКУС | F10: 52 | G10: 3406 | H10: 5450
A11: 37289 | C11: 65 | E11: СУХАЯ СМЕСЬ ДЛЯ КОКТЕЙЛЯ NATURAL BALANCE - ШОКОЛАДНЫЙ ВКУС | F11: 52 | G11: 3406 | H11: 5450
A12: 37290 | C12: 65 | E12: СУХАЯ СМЕСЬ ДЛЯ КОКТЕЙЛЯ NATURAL BALANCE - ВАНИЛЬНЫЙ ВКУС | F12: 52 | G12: 3406 | H12: 5450
A13: 38556 | C13: 161 | E13: КОМПЛЕКС «ОМЕГА-3» | F13: 26 | G13: 1687 | H13: 2700
A14: 38557 | C14: 70 | E14: КОМПЛЕКС «АСТАКСАНТИН И ЭКСТРАКТ ЧЕРНИКИ» | F14: 32 | G14: 2062 | H14: 3300
A15: 38558 | C15: 70 | E15: КОМПЛЕКС «МУЛЬТИВИТАМИНЫ И МИНЕРАЛЫ» ДЛЯ МУЖЧИН | F15: 32 | G15: 2062 | H15: 3300
A16: 38559 | C16: 70 | E16: КОМПЛЕКС «МУЛЬТИВИТАМИНЫ И МИНЕРАЛЫ» ДЛЯ ЖЕНЩИН | F16: 32 | G16: 2062 | H16: 3300
A17: 38836 | C17: 69 | E17: WELLOSOPHY WELLNESS PACK ДЛЯ МУЖЧИН | F17: 50 | G17: 3218 | H17: 5150
A18: 38838 | C18: 69 | E18: WELLOSOPHY WELLNESS PACK ДЛЯ ЖЕНЩИН | F18: 50 | G18: 3218 | H18: 5150
A19: 40745 | C19: 66 | E19: ПИТАТЕЛЬНЫЙ СУП ДЛЯ КОНТРОЛЯ ВЕСА - ГРИБНОЙ ВКУС | F19: 70 | G19: 4156 | H19: 6650
A20: 44220 | C20: 70 | E20: ВИТАМИН D3 | F20: 19 | G20: 1219 | H20: 1950
A21: 44221 | C21: 70 | E21: КОМПЛЕКС «МОРСКОЙ МАГНИЙ И ВИТАМИН B6» | F21: 22 | G21: 1437 | H21: 2300
A22: 45138 | B22: 0.23857143 | C22: 61 | E22: КРЕМ ДЛЯ ЛИЦА WELLOSOPHY-РАЗГЛАЖИВАНИЕ И ОБНОВЛЕНИЕ | F22: 15 | G22: 999 | H22: 1599
A23: 45139 | B23: 0.24566038 | C23: 61 | E23: ГЕЛЬ-СЫВОРОТКА ДЛЯ ЛИЦА WELLOSOPHY-ОМОЛОЖЕНИЕ И ВОССТАНОВЛЕНИЕ | F23: 19 | G23: 1250 | H23: 1999
A24: 45147 | E24: МАСЛО-СЫВОРОТКА WELLOSOPHY - УПРУГОСТЬ И СИЯНИЕ | F24: 20 | G24: 1312 | H24: 2100
A25: 45148 | B25: 0.29 | C25: 61 | E25: БАЛЬЗАМ ДЛЯ КОЖИ ВОКРУГ ГЛАЗ WELLOSOPHY-УВЛАЖНЕНИЕ И ВОССТАНОВЛЕНИЕ | F25: 13 | G25: 843 | H25: 1349
A26: 45149 | B26: 0.24206897 | C26: 61 | E26: ОЧИЩАЮЩЕЕ СРЕДСТВО ДЛЯ ЛИЦА WELLOSOPHY-СИЯНИЕ И БАЛАНС | F26: 11 | G26: 687 | H26: 1099
A27: 45152 | B27: 0.34636364 | C27: 59 | E27: МАСКА ДЛЯ ЛИЦА WELLOSOPHY - ОТШЕЛУШИВАНИЕ И ТОНИЗИРОВАНИЕ | F27: 7 | G27: 449 | H27: 719
A28: 45273 | C28: 70 | E28: НУТРИКОМПЛЕКС ДЛЯ КОЖИ, ВОЛОС И НОГТЕЙ | F28: 39 | G28: 2562 | H28: 4100
A29: 45290 | B29: 0.35241379 | C29: 58 | E29: МИСТ ДЛЯ ЛИЦА WELLOSOPHY - ВОССТАНОВЛЕНИЕ И УВЛАЖНЕНИЕ | F29: 9 | G29: 587 | H29: 939
A30: 45306 | C30: 67 | E30: ПИТАТЕЛЬНЫЙ КОКТЕЙЛЬ ДЛЯ КОНТРОЛЯ ВЕСА - ВАНИЛЬНЫЙ ВКУС | F30: 70 | G30: 4156 | H30: 6650
A31: 45307 | C31: 67 | E31: ПИТАТЕЛЬНЫЙ КОКТЕЙЛЬ ДЛЯ КОНТРОЛЯ ВЕСА - ШОКОЛАДНЫЙ ВКУС | F31: 70 | G31: 4156 | H31: 6650
A32: 45309 | C32: 70 | E32: КОМПЛЕКС "МОРСКОЙ КАЛЬЦИЙ И ВИТАМИН D" | F32: 26 | G32: 1687 | H32: 2700
A33: 45312 | B33: 0.40777778 | C33: 71 | E33: ПРЕБИОТИЧЕСКИЙ НАПИТОК С ПИЩЕВЫМИ ВОЛОКНАМИ | F33: 15 | G33: 999 | H33: 1599
A34: 46068 | C34: 71 | E34: МЕРНАЯ ЛОЖКА | F34: 1 | G34: 46 | H34: 149
A35: 46664 | C35: 66 | E35: ШЕЙКЕР | F35: 15 | G35: 500 | H35: 1599
A36: 47784 | B36: 0.39815534 | C36: 63 | E36: НАБОР ДЛЯ УХОДА ЗА КОЖЕЙ WELLOSOPHY+НУТРИКОМПЛЕКС | F36: 59 | G36: 3875 | H36: 6199
A37: 47785 | B37: 0.40010526 | C37: 62 | E37: БАЗОВЫЙ НАБОР ДЛЯ УХОДА ЗА КОЖЕЙ+КОМПЛЕКС "АСТАКСАНТИН И ЭКСТРАКТ ЧЕРНИКИ" | F37: 65 | G37: 3562 | H37: 5699
A38: 47788 | B38: 0.40108911 | C38: 63 | E38: НАБОР WELLOSOPHY+КОМПЛЕКС"МОРСКОЙ МАГНИЙ И ВИТАМИН B6" | F38: 58 | G38: 3781 | H38: 6049
A39: 47847 | B39: 0.4033871 | C39: 60 | E39: БАЗОВЫЙ НАБОР ДЛЯ УХОДА ЗА КОЖЕЙ WELLOSOPHY | F39: 42 | G39: 2312 | H39: 3699
E40: ДЕКОРАТИВНАЯ КОСМЕТИКА
...
