Workbook
Name Color_GM: #REF!
Name Target_GM: #REF!
Name МЯГКИЙ_ДВУХСТОРОННИЙ_КАРАНДАШ_ДЛЯ_ГЛАЗ___СЛИВОЧНАЯ_КАРАМЕЛЬ__СТР._83_КАТАЛОГА: '[1]10 КАТАЛОГ`08 (1)'!#REF!
Name МЯГКИЙ_ДВУХСТОРОННИЙ_КАРАНДАШ_ДЛЯ_ГЛАЗ___СЛИВОЧНАЯ_КАРАМЕЛЬ__СТР._83_КАТАЛОГА: '[1]10 КАТАЛОГ`08 (1)'!#REF!
Name МЯГКИЙ_ДВУХСТОРОННИЙ_КАРАНДАШ_ДЛЯ_ГЛАЗ___СЛИВОЧНАЯ_КАРАМЕЛЬ__СТР._83_КАТАЛОГА: '05 КАТАЛОГ`26 (1)'!#REF!

Sheet 05 КАТАЛОГ`26 (1)
E1: НОВИНКИ КАТАЛОГА
A2: КОД | B2: СКИДКА | C2: СТР. | D2: АКЦИЯ | E2: НАИМЕНОВАНИЕ | F2: ББ | G2: ОП | H2: ПЦ
A3: 45286 | B3: 0.39052632 | C3: 17 | E3: ОТШЕЛУШИВАЮЩИЙ СКРАБ ДЛЯ ЛИЦА OPTIMALS | F3: 5 | G3: 356 | H3: 579
A4: 45287 | B4: 0.39052632 | C4: 10 | E4: МИЦЕЛЛЯРНАЯ ВОДА OPTIMALS | F4: 5 | G4: 356 | H4: 579
A5: 47278 | B5: 0.39052632 | C5: 11 | E5: УВЛАЖНЯЮЩИЙ ТОНИК OPTIMALS | F5: 5 | G5: 356 | H5: 579
A6: 47682 | B6: 0.400625 | C6: 15 | E6: ЛЁГКИЙ АНТИВОЗРАСТНОЙ КРЕМ ДЛЯ ЛИЦА OPTIMALS | F6: 9 | G6: 590 | H6: 959
A7: 47683 | B7: 0.400625 | C7: 15 | E7: НАСЫЩЕННЫЙ АНТИВОЗРАСТНОЙ КРЕМ ДЛЯ ЛИЦА OPTIMALS | F7: 9 | G7: 590 | H7: 959
A8: 47684 | B8: 0.3937931 | C8: 13 | E8: РАЗГЛАЖИВАЮЩИЙ КРЕМ-ФИЛЛЕР ДЛЯ ЛИЦА OPTIMALS | F8: 8 | G8: 540 | H8: 879
A9: 47685 | B9: 0.400625 | C9: 14 | E9: АНТИВОЗРАСТНАЯ СЫВОРОТКА OPTIMALS | F9: 9 | G9: 590 | H9: 959
A10: 48656 | B10: 0.562 | C10: 47 | E10: ОТТЕНОЧНЫЙ БАЛЬЗАМ ДЛЯ ГУБ ONCOLOUR - ВАНИЛЬНЫЙ КРУАССАН | F10: 2 | G10: 134 | H10: 219
A11: 48657 | B11: 0.562 | C11: 47 | E11: - ТЁПЛЫЙ ГЛИНТВЕЙН | F11: 2 | G11: 134 | H11: 219
A12: 48658 | B12: 0.562 | C12: 47 | E12: - РОЗОВЫЙ МАРМЕЛАД | F12: 2 | G12: 134 | H12: 219
A13: 48659 | B13: 0.562 | C13: 47 | E13: - ВИШНЁВОЕ ЖЕЛЕ | F13: 2 | G13: 134 | H13: 219
A14: 48938 | C14: 14 | E14: АНТИВОЗРАСТНАЯ СЫВОРОТКА OPTIMALS (ПРОБНИК) | F14: - | G14: - | H14: 40
A15: 48939 | C15: 15 | E15: НАСЫЩЕННЫЙ АНТИВОЗРАСТНОЙ КРЕМ ДЛЯ ЛИЦА OPTIMALS (ПРОБНИК) | F15: - | G15: - | H15: 40
A16: 48940 | C16: 15 | E16: ЛЁГКИЙ АНТИВОЗРАСТНОЙ КРЕМ ДЛЯ ЛИЦА OPTIMALS (ПРОБНИК) | F16: - | G16: - | H16: 40
E18: НОВИНКИ WELLOSOPHY
A19: КОД | B19: СКИДКА | C19: СТР. | D19: АКЦИЯ | E19: НАИМЕНОВАНИЕ | F19: ББ | G19: ОП | H19: ПЦ
A20: 48896 | B20: 0.2538806 | C20: 7 | E20: КОМПЛЕКС ORIMETABO RE-BALANCE | F20: 47 | G20: 3073 | H20: 4999
E22: WELLOSOPHY
A23: КОД | B23: СКИДКА | C23: СТР. | D23: АКЦИЯ | E23: НАИМЕНОВАНИЕ | F23: ББ | G23: ОП | H23: ПЦ
A24: 29699 | C24: 113 | E24: КОМПЛЕКС «МУЛЬТИВИТАМИНЫ И МИНЕРАЛЫ» ДЛЯ ДЕТЕЙ | F24: 24 | G24: 1537 | H24: 2500
A25: 37285 | C25: 115 | E25: СУХАЯ СМЕСЬ ДЛЯ КОКТЕЙЛЯ NATURAL BALANCE - КЛУБНИЧНЫЙ ВКУС | F25: 54 | G25: 3442 | H25: 5600
A26: 37289 | C26: 115 | E26: СУХАЯ СМЕСЬ ДЛЯ КОКТЕЙЛЯ NATURAL BALANCE - ШОКОЛАДНЫЙ ВКУС | F26: 54 | G26: 3442 | H26: 5600
A27: 37290 | C27: 115 | E27: СУХАЯ СМЕСЬ ДЛЯ КОКТЕЙЛЯ NATURAL BALANCE - ВАНИЛЬНЫЙ ВКУС | F27: 54 | G27: 3442 | H27: 5600
A28: 38556 | B28: 0.25035714 | C28: 119 | E28: КОМПЛЕКС «ОМЕГА-3» | F28: 20 | G28: 1290 | H28: 2099
A29: 38557 | C29: 117 | E29: КОМПЛЕКС «АСТАКСАНТИН И ЭКСТРАКТ ЧЕРНИКИ» | F29: 33 | G29: 2121 | H29: 3450
A30: 38558 | C30: 118 | E30: КОМПЛЕКС «МУЛЬТИВИТАМИНЫ И МИНЕРАЛЫ» ДЛЯ МУЖЧИН | F30: 33 | G30: 2121 | H30: 3450
A31: 38559 | C31: 118 | E31: КОМПЛЕКС «МУЛЬТИВИТАМИНЫ И МИНЕРАЛЫ» ДЛЯ ЖЕНЩИН | F31: 33 | G31: 2121 | H31: 3450
A32: 38836 | C32: 113 | E32: WELLOSOPHY WELLNESS PACK ДЛЯ МУЖЧИН | F32: 51 | G32: 3258 | H32: 5300
A33: 38838 | C33: 113 | E33: WELLOSOPHY WELLNESS PACK ДЛЯ ЖЕНЩИН | F33: 51 | G33: 3258 | H33: 5300
A34: 40745 | C34: 114 | E34: ПИТАТЕЛЬНЫЙ СУП ДЛЯ КОНТРОЛЯ ВЕСА - ГРИБНОЙ ВКУС | F34: 70 | G34: 4242 | H34: 6900
A35: 44220 | B35: 0.4005 | C35: 121 | E35: ВИТАМИН D3 | F35: 11 | G35: 737 | H35: 1199
A36: 44221 | C36: 120 | E36: КОМПЛЕКС «МОРСКОЙ МАГНИЙ И ВИТАМИН B6» | F36: 23 | G36: 1476 | H36: 2400
A37: 45138 | B37: 0.25045455 | C37: 110 | E37: КРЕМ ДЛЯ ЛИЦА WELLOSOPHY-РАЗГЛАЖИВАНИЕ И ОБНОВЛЕНИЕ | F37: 16 | G37: 1013 | H37: 1649
A38: 45147 | B38: 0.50045455 | C38: 25 | E38: МАСЛО-СЫВОРОТКА WELLOSOPHY - УПРУГОСТЬ И СИЯНИЕ | F38: 10 | G38: 675 | H38: 1099
A39: 45148 | B39: 0.3005 | C39: 110 | E39: БАЛЬЗАМ ДЛЯ КОЖИ ВОКРУГ ГЛАЗ WELLOSOPHY-УВЛАЖНЕНИЕ И ВОССТАНОВЛЕНИЕ | F39: 13 | G39: 860 | H39: 1399
A40: 45149 | B40: 0.40066667 | C40: 110 | E40: ОЧИЩАЮЩЕЕ СРЕДСТВО ДЛЯ ЛИЦА WELLOSOPHY-СИЯНИЕ И БАЛАНС | F40: 8 | G40: 552 | H40: 899
A41: 45273 | C41: 120 | E41: НУТРИКОМПЛЕКС ДЛЯ КОЖИ, ВОЛОС И НОГТЕЙ | F41: 41 | G41: 2613 | H41: 4250
A42: 45289 | B42: 0.49757576 | C42: 24 | E42: НОЧНОЙ ЭЛИКСИР WELLOSOPHY-ВОССТАНОВЛЕНИЕ И РАЗГЛАЖИВАНИЕ | F42: 8 | G42: 509 | H42: 829
...

Sheet 05 КАТАЛОГ`26 (2)
A1: ПРОБНИК | B1: ПРОДУКТ | C1: ТЕСТЕРЫ | D1: ЦЕНА
A2: 11037 | B2: 42490 | C2: ТУАЛЕТНАЯ ВОДА ASCENDANT | D2: 40
A3: 11365 | B3: 42495 | C3: ПАРФЮМЕРНАЯ ВОДА AMBER ELIXIR | D3: 40
A4: 22443 | B4: 42751 | C4: ПАРФЮМИРОВАННАЯ ВОДА LOVE POTION | D4: 40
A5: 30129 | B5: 42507 | C5: ТУАЛЕТНАЯ ВОДА ECLAT FEMME | D5: 40
A6: 30557 | B6: 30468 | C6: ТУАЛЕТНОЙ ВОДЫ BE THE LEGEND | D6: 40
A7: 30885 | B7: 42519 | C7: ПАРФЮМЕРНАЯ ВОДА POSSESS | D7: 40
A8: 31817 | B8: 47511 | C8: ПАРФЮМИРОВАННАЯ ВОДА GIORDANI GOLD ESSENZA | D8: 40
A9: 33649 | B9: 33650 | C9: ПАРФЮМЕРНАЯ ВОДА POSSESS THE SECRET MAN | D9: 40
A10: 35656 | B10: 37766 | C10: ТУАЛЕТНАЯ ВОДА JOYCE ROSE | D10: 40
A11: 35666 | B11: 35665 | C11: ТУАЛЕТНАЯ ВОДА GLACIER | D11: 40
A12: 38548 | B12: 43122 | C12: ЖЕНСКАЯ ПАРФЮМЕРНАЯ ВОДА NORDIC WATERS | D12: 40
A13: 40722 | B13: 40667 | C13: ТУАЛЕТНАЯ ВОДА GLACIER EXTREME | D13: 40
A14: 41185 | B14: 40794 | C14: ДНЕВНОЙ КРЕМ-КОМФОРТ NOVAGE SKINRELIEF PRO RESILIENT SPF 30 | D14: 40
A15: 41771 | B15: 42785 | C15: ТУАЛЕТНАЯ ВОДА LUCIA | D15: 40
A16: 43937 | B16: 38538 | C16: ПАРФЮМЕРНАЯ ВОДА GIORDANI GOLD MAN | D16: 40
A17: 44289 | B17: 44288 | C17: ТУАЛЕТНАЯ ВОДА OH! SWEET DULCE DE LECHE | D17: 40
A18: 44306 | B18: 44300 | C18: ПАРФЮМИРОВАННАЯ ВОДА LOVE POTION SENSUAL RUBY | D18: 40
A19: 44847 | B19: 42101 | C19: СТОЙКАЯ МИНЕРАЛЬНАЯ ТОНАЛЬНАЯ ОСНОВА GIORDANI GOLD - НЕЙТРАЛЬНЫЙ ВАНИЛЬНЫЙ | D19: 40
A20: 44853 | B20: 42107 | C20: - ЕСТЕСТВЕННЫЙ БЕЖЕВЫЙ | D20: 40
A21: 44857 | B21: 42653 | C21: - РОСКОШНАЯ ОРХИДЕЯ | D21: 40
A22: 44862 | B22: 42658 | C22: - БЕЗУПРЕЧНЫЙ РОЗОВЫЙ | D22: 40
A23: 44865 | B23: 42112 | C23: МУЛЬТИФУНКЦИОНАЛЬНЫЙ СС-КРЕМ GG SPF 30 - СВЕТЛЫЙ | D23: 40
A24: 44866 | B24: 42113 | C24: - ЕСТЕСТВЕННЫЙ | D24: 40
A25: 44871 | B25: 42236 | C25: АНТИВОЗРАСТНАЯ ТОН. ОСНОВА С ПРЕБИОТИЧЕСКОЙ СЫВОРОТКОЙ GIORDANI GOLD - СЛОНОВАЯ КОСТЬ (НЕЙТРАЛЬНЫЙ) | D25: 55
A26: 44872 | B26: 42236 | C26: АНТИВОЗРАСТНАЯ ТОН. ОСНОВА С ПРЕБИОТИЧЕСКОЙ СЫВОРОТКОЙ GIORDANI GOLD - БЕЖЕВЫЙ (ТЁПЛЫЙ) | D26: 55
A27: 45395 | B27: 38497 | C27: ПАРФЮМЕРНАЯ ВОДА DIVINE | D27: 40
A28: 45636 | B28: 43244 | C28: СИЯЮЩАЯ ТОНАЛЬНАЯ ОСНОВА GIORDANI GOLD SPF 25 - ТЁПЛЫЙ ФАРФОРОВЫЙ | D28: 40
A29: 45637 | B29: 43245 | C29: - НЕЙТРАЛЬНЫЙ БЕЖ | D29: 40
A30: 45639 | B30: 43247 | C30: - СЛОНОВАЯ КОСТЬ | D30: 40
A31: 45696 | B31: 41365 | C31: ДНЕВНОЙ КРЕМ WAUNT «ДЗЕН-ЭФФЕКТ» | D31: 40
A32: 45880 | B32: 44308 | C32: ТУАЛЕТНАЯ ВОДА VENTURE POWER | D32: 40
A33: 45891 | B33: 45890 | C33: ТУАЛЕТНАЯ ВОДА EXCITE FOR HIM | D33: 40
A34: 46054 | B34: 46052 | C34: ПАРФЮМЕРНАЯ ВОДА VOLARE TENDER | D34: 40
A35: 46055 | B35: 45967 | C35: МУЖСКИЕ ДУХИ GIORDANI GOLD ESSENZA MAN | D35: 40
A36: 46106 | B36: 45138 | C36: КРЕМ ДЛЯ ЛИЦА WELLOSOPHY-РАЗГЛАЖИВАНИЕ И ОБНОВЛЕНИЕ | D36: 40
A37: 46107 | B37: 45139 | C37: ГЕЛЬ-СЫВОРОТКА ДЛЯ ЛИЦА WELLOSOPHY-ОМОЛОЖЕНИЕ И ВОССТАНОВЛЕНИЕ | D37: 40
A38: 46335 | B38: 46329 | C38: ТОНАЛЬНАЯ ОСНОВА С ЭФФЕКТОМ СИЯНИЯ THE ONE - ВАНИЛЬНЫЙ | D38: 55
A39: 46340 | B39: 46333 | C39: - БЕЖЕВЫЙ НЕЙТРАЛЬНЫЙ | D39: 55
A40: 46606 | B40: 46064 | C40: МУЖСКАЯ ПАРФЮМЕРНАЯ ВОДА NORDIC WATERS INFINITE BLUE | D40: 40
...

Sheet 05 КАТАЛОГ`26 (3)
B1: ПРОДУКЦИЯ, НЕ ПРЕДСТАВЛЕННАЯ В КАТАЛОГЕ
A2: КОД | B2: НАИМЕНОВАНИЕ | C2: ББ | D2: ОП | E2: ПЦ
B3: ПОМАДЫ, БЛЕСКИ И КАРАНДАШИ ДЛЯ ГУБ
A4: 37731 | B4: КАРАНДАШ ДЛЯ ГУБ THE ONE - РОЗОВЫЙ | C4: 5 | D4: 344 | E4: 560
B5: АРОМАТЫ
A6: 37772 | B6: ТУАЛЕТНАЯ ВОДА JOYCE JADE | C6: 16 | D6: 1045 | E6: 1700
A7: 42828 | B7: ТУАЛЕТНАЯ ВОДА WOMEN'S COLLECTION CHERRY BLOSSOM | C7: 21 | D7: 1383 | E7: 2250
A8: 44288 | B8: ТУАЛЕТНАЯ ВОДА OH! SWEET DULCE DE LECHE | C8: 21 | D8: 1383 | E8: 2250
A9: 33958 | B9: ПАРФЮМИРОВАННЫЙ СПРЕЙ ДЛЯ ТЕЛА LOVE POTION SO TEMPTING | C9: 15 | D9: 983 | E9: 1600
A10: 38526 | B10: ПАРФЮМИРОВАННЫЙ СПРЕЙ ДЛЯ ТЕЛА LOVE POTION BLOSSOM KISS | C10: 15 | D10: 983 | E10: 1600
A11: 42518 | B11: ТУАЛЕТНАЯ ВОДА MEN'S COLLECTION DARK WOOD | C11: 21 | D11: 1383 | E11: 2250
B12: УХОД ДЛЯ ТЕЛА
A13: 12760 | B13: СПЕЦИАЛЬНОЕ СМЯГЧАЮЩЕЕ СРЕДСТВО | C13: 4 | D13: 246 | E13: 400
A14: 34499 | B14: УСПОКАИВАЮЩИЙ ГЕЛЬ ДЛЯ ИНТИМНОЙ ГИГИЕНЫ FEMINELLE | C14: 7 | D14: 461 | E14: 750
A15: 34500 | B15: ОСВЕЖАЮЩИЙ ГЕЛЬ ДЛЯ ИНТИМНОЙ ГИГИЕНЫ FEMINELLE | C15: 7 | D15: 461 | E15: 750
A16: 34504 | B16: СМЯГЧАЮЩИЙ КРЕМ-ГЕЛЬ ДЛЯ ИНТИМНОЙ ГИГИЕНЫ FEMINELLE | C16: 7 | D16: 461 | E16: 750
A17: 39377 | B17: ОСВЕЖАЮЩИЙ ГЕЛЬ ДЛЯ ДУША С ОКЕАНСКИМ АККОРДОМ SCENTS & MOMENTS | C17: 4 | D17: 246 | E17: 400
A18: 39389 | B18: РАССЛАБЛЯЮЩИЙ ГЕЛЬ ДЛЯ ДУША С ЛАВАНДОЙ SCENTS & MOMENTS | C18: 4 | D18: 246 | E18: 400
A19: 39399 | B19: ЧУВСТВЕННЫЙ ГЕЛЬ ДЛЯ ДУША С ПИОНОМ SCENTS & MOMENTS | C19: 4 | D19: 246 | E19: 400
A20: 39426 | B20: БОДРЯЩИЙ ГЕЛЬ ДЛЯ ДУША С РОЗОВЫМ ГРЕЙПФРУТОМ SCENTS & MOMENTS | C20: 4 | D20: 246 | E20: 400
A21: 41264 | B21: БОДРЯЩИЙ ГЕЛЬ ДЛЯ ДУША С ОРГАНИЧЕСКОЙ КОКОСОВОЙ ВОДОЙ И ДЫНЕЙ LOVE NATURE | C21: 5 | D21: 295 | E21: 480
A22: 41265 | B22: БОДРЯЩИЙ ГЕЛЬ ДЛЯ ДУША LOVE NATURE. БОЛЬШОЙ ОБЪЁМ | C22: 8 | D22: 522 | E22: 850
A23: 41280 | B23: ОСВЕЖАЮЩИЙ ГЕЛЬ ДЛЯ ДУША С ЗЕЛЁНЫМ ЧАЕМ И ОГУРЦОМ LOVE NATURE | C23: 5 | D23: 295 | E23: 480
A24: 41283 | B24: ПИТАТЕЛЬНОЕ МАСЛО ДЛЯ ТЕЛА, ЛИЦА И ВОЛОС С ОРГАНИЧЕСКИМ АВОКАДО LOVE NATURE | C24: 13 | D24: 817 | E24: 1330
... A40: 48548 | B40: ГУБКА ДЛЯ ДУША | C40: 3 | D40: 86 | E40: 279
B41: ДЕЗОДОРАНТЫ
A42: 33144 | B42: СПРЕЙ ДЕЗОДОРАНТ С УХАЖИВАЮЩИМ КОМПЛЕКСОМ ACTIVELLE | C42: 6 | D42: 399 | E42: 650
A43: 33147 | B43: СПРЕЙ ДЕЗОДОРАНТ ДЛЯ ЭКСТРЕМАЛЬНОЙ ЗАЩИТЫ ACTIVELLE | C43: 6 | D43: 399 | E43: 650
A44: 41311 | B44: СПРЕЙ ДЕЗОДОРАНТ БЕЗ БЕЛЫХ СЛЕДОВ ACTIVELLE | C44: 6 | D44: 399 | E44: 650
A45: 43927 | B45: ШАРИКОВЫЙ ДЕЗОДОРАНТ NORTH FOR MEN ULTIMATE BALANCE | C45: 5 | D45: 326 | E45: 530
A46: 46382 | B46: СПРЕЙ ДЕЗОДОРАНТ-АНТИПЕРСПИРАНТ ДЛЯ МАКСИМАЛЬНОЙ СВЕЖЕСТИ ACTIVELLE | C46: 6 | D46: 399 | E46: 650
B47: УХОД ДЛЯ РУК
A48: 41335 | B48: КРЕМ ДЛЯ РУК И НОГТЕЙ С ОРГАНИЧЕСКИМ МАСЛОМ МАКАДАМИИ LOVE NATURE | C48: 4 | D48: 264 | E48: 430
A49: 41341 | B49: КРЕМ ДЛЯ РУК С ОРГАНИЧЕСКИМ РОЗОВЫМ ГРЕЙПФРУТОМ LOVE NATURE | C49: 4 | D49: 264 | E49: 430
A50: 46219 | B50: МИНИ-КРЕМ ДЛЯ РУК | C50: 2 | D50: 135 | E50: 220
A51: 47536 | B51: КРЕМ ДЛЯ РУК И ТЕЛА MILK & HONEY GOLD - МАГНОЛИЯ | C51: 9 | D51: 615 | E51: 1000
A52: 47537 | B52: ЖИДКОЕ МЫЛО ДЛЯ РУК И ТЕЛА MILK & HONEY GOLD - МАГНОЛИЯ | C52: 8 | D52: 522 | E52: 850
A53: 46979 | B53: ПАРФЮМИРОВАННЫЙ КРЕМ ДЛЯ РУК LOVE POTION CHERRY ON TOP | C53: 6 | D53: 363 | E53: 590
A54: 47202 | B54: ЗАЩИТНЫЙ КРЕМ ДЛЯ РУК И НОГТЕЙ С ОРГАНИЧЕСКИМ ЭКСТРАКТОМ МАРАКУЙИ LOVE NATURE | C54: 4 | D54: 264 | E54: 430
A55: 46621 | B55: ЛОСЬОН ДЛЯ РУК И ТЕЛА NEON VIBES | C55: 9 | D55: 615 | E55: 1000
...

Sheet СПЕЦПРЕДЛОЖЕНИЯ
A1: КОД | B1: АКЦИЯ | C1: Наименование | D1: ББ | E1: ОП | F1: ПЦ
C2: предложение со стр. 8-9
A3: 46045 | B3: + | C3: МУЖСКАЯ ПАРФЮМЕРНАЯ ВОДА MISTER GIORDANI | D3: 39 | E3: 2521 | F3: 4100
A4: 47513 | B4: + | C4: ПАРФЮМЕРНАЯ ВОДА MISS GIORDANI | D4: 39 | E4: 2521 | F4: 4100
C5: ЦЕНА 1499 РУБ. ПРИ ЗАКАЗЕ НА 3000 РУБ. ИЗ ЭТОГО КАТАЛОГА ИЛИ НА САЙТЕ В ПЕРИОД ДЕЙСТВИЯ КАТАЛОГА (КРОМЕ ПРОДУКТОВ-УЧАСТНИКОВ АКЦИИ 46045, 47513, 29699, 38836, 38838, 40745, 45306, 45307, 37285, 37289, 37290) | D5: 14 | E5: 922 | F5: 1499
C6: предложение со стр. 10-11
A7: 45287 | B7: + | C7: МИЦЕЛЛЯРНАЯ ВОДА OPTIMALS | D7: 5 | E7: 356 | F7: 579
A8: 47278 | B8: + | C8: УВЛАЖНЯЮЩИЙ ТОНИК OPTIMALS | D8: 5 | E8: 356 | F8: 579
C9: ЦЕНА 299 РУБ. ПРИ ЗАКАЗЕ ЛЮБОГО СРЕДСТВА OPTIMALS СО СТР. 12-17 (КРОМЕ 45287, 47278 И ПРОБНИКОВ 48938, 48939, 48940) | D9: 3 | E9: 184 | F9: 299
C10: предложение со стр. 29
A11: 46134 | B11: + | C11: ВЫРАВНИВАЮЩИЙ BB-КРЕМ С SPF 15 THE ONE - ВАНИЛЬНЫЙ | D11: 7 | E11: 448 | F11: 729
A12: 46135 | B12: + | C12: - СВЕТЛЫЙ БЕЖ | D12: 7 | E12: 448 | F12: 729
A13: 46136 | B13: + | C13: - СЛОНОВАЯ КОСТЬ | D13: 7 | E13: 448 | F13: 729
A14: 46137 | B14: + | C14: - ТЁПЛЫЙ БЕЖ | D14: 7 | E14: 448 | F14: 729
A15: 46435 | B15: + | C15: КРЕМОВАЯ ГУБНАЯ ПОМАДА THE ONE SMART SYNC - РУМЯНЫЙ НЮД | D15: 6 | E15: 381 | F15: 619
A16: 46436 | B16: + | C16: - ЗОЛОТАЯ КАРАМЕЛЬ | D16: 6 | E16: 381 | F16: 619
A17: 46437 | B17: + | C17: - ТЁПЛОЕ КАКАО | D17: 6 | E17: 381 | F17: 619
A18: 46438 | B18: + | C18: - МЯГКИЙ ТЕРРАКОТОВЫЙ | D18: 6 | E18: 381 | F18: 619
A19: 46439 | B19: + | C19: - РОЗОВЫЙ КЛЕВЕР | D19: 6 | E19: 381 | F19: 619
A20: 46440 | B20: + | C20: - НЕЖНЫЙ РОЗОВЫЙ | D20: 6 | E20: 381 | F20: 619
A21: 46441 | B21: + | C21: - РОЗОВОЕ ДЕРЕВО | D21: 6 | E21: 381 | F21: 619
A22: 46442 | B22: + | C22: - МЯГКИЙ ПУРПУРНЫЙ | D22: 6 | E22: 381 | F22: 619
... A30: 46896 | B30: + | C30: ТУШЬ ДЛЯ РЕСНИЦ С ЭФФЕКТОМ ОБЪЁМА THE ONE ЧЁРНЫЙ | D30: 4 | E30: 276 | F30: 449
C31: ЛЮБОЙ ОТТЕНОК ВВ-КРЕМА + ЛЮБОЙ ОТТЕНОК КРЕМОВОЙ ГУБНОЙ ПОМАДЫ + ТУШЬ ДЛЯ РЕСНИЦ ЗА 1199 РУБ. | D31: 11 | E31: 739 | F31: 1199
C32: предложение со стр. 31
A33: 42112 | B33: + | C33: МУЛЬТИФУНКЦИОНАЛЬНЫЙ СС-КРЕМ GG SPF 30 - СВЕТЛЫЙ | D33: 12 | E33: 768 | F33: 1249
A34: 42113 | B34: + | C34: - ЕСТЕСТВЕННЫЙ | D34: 12 | E34: 768 | F34: 1249
A35: 44821 | B35: + | C35: ЖИДКАЯ ГУБНАЯ ПОМАДА-ЭЛИКСИР SPF 15 GIORDANI GOLD - БАРХАТНЫЙ РУМЯНЕЦ | D35: 8 | E35: 516 | F35: 839
A36: 44822 | B36: + | C36: - НЕЖНЫЙ НЮД | D36: 8 | E36: 516 | F36: 839
A37: 44823 | B37: + | C37: - МЯГКАЯ КАРАМЕЛЬ | D37: 8 | E37: 516 | F37: 839
A38: 44824 | B38: + | C38: - ПРИГЛУШЁННЫЙ КОРАЛЛ | D38: 8 | E38: 516 | F38: 839
A39: 44825 | B39: + | C39: - ПРЯНАЯ РОЗА | D39: 8 | E39: 516 | F39: 839
A40: 44826 | B40: + | C40: - ШОКОЛАДНЫЙ ВЕЛЮР | D40: 8 | E40: 516 | F40: 839
A41: 44827 | B41: + | C41: - РОЗОВОЕ ДЕРЕВО | D41: 8 | E41: 516 | F41: 839
A42: 44828 | B42: + | C42: - ВИННАЯ ЯГОДА | D42: 8 | E42: 516 | F42: 839
A43: 44829 | B43: + | C43: - РОСКОШНЫЙ АЛЫЙ | D43: 8 | E43: 516 | F43: 839
A44: 44830 | B44: + | C44: - ПЫШНАЯ ВИШНЯ | D44: 8 | E44: 516 | F44: 839
A45: 48645 | B45: + | C45: СУПЕРТУШЬ ДЛЯ РЕСНИЦ GIORDANI GOLD. ЛИМИТИРОВАННЫЙ ВЫПУСК | D45: 8 | E45: 516 | F45: 839
C46: ЛЮБОЙ ОТТЕНОК СС-КРЕМА + ЛЮБОЙ ОТТЕНОК ЖИДКОЙ ГУБНОЙ ПОМАДЫ-ЭЛИКСИРА + СУПЕРТУШЬ ДЛЯ РЕСНИЦ ЗА 1899 РУБ. | D46: 18 | E46: 1168 | F46: 1899
C47: предложение со стр. 104
...
