Workbook

Sheet КАЛЬКУЛЯТОР
A1: КОД | B1: КОЛ-ВО | C1: СКИДКА | D1: НАИМЕНОВАНИЕ | E1: ББ | F1: ОП | G1: ПЦ
D2: С У М М А | E2: =SUM(E3:E900) -> 0 | F2: =SUM(F3:F900) -> 0 | G2: =SUM(G3:G900) -> 0
C3: =IF(A3=""," ",VLOOKUP(A3,'18.11-07.12.2024'!A:H,2,FALSE)) | D3: =IF(A3=""," ",VLOOKUP(A3,'18.11-07.12.2024'!A:H,5,FALSE)) | E3: =IF(A3=""," ",B3*VLOOKUP(A3,'18.11-07.12.2024'!A:H,6,FALSE)) | F3: =IF(A3=""," ",B3*VLOOKUP(A3,'18.11-07.12.2024'!A:H,7,FALSE)) | G3: =IF(A3=""," ",B3*VLOOKUP(A3,'18.11-07.12.2024'!A:H,8,FALSE))
C4: =IF(A4=""," ",VLOOKUP(A4,'18.11-07.12.2024'!A:H,2,FALSE)) | D4: =IF(A4=""," ",VLOOKUP(A4,'18.11-07.12.2024'!A:H,5,FALSE)) | E4: =IF(A4=""," ",B4*VLOOKUP(A4,'18.11-07.12.2024'!A:H,6,FALSE)) | F4: =IF(A4=""," ",B4*VLOOKUP(A4,'18.11-07.12.2024'!A:H,7,FALSE)) | G4: =IF(A4=""," ",B4*VLOOKUP(A4,'18.11-07.12.2024'!A:H,8,FALSE))
C5: =IF(A5=""," ",VLOOKUP(A5,'18.11-07.12.2024'!A:H,2,FALSE)) | D5: =IF(A5=""," ",VLOOKUP(A5,'18.11-07.12.2024'!A:H,5,FALSE)) | E5: =IF(A5=""," ",B5*VLOOKUP(A5,'18.11-07.12.2024'!A:H,6,FALSE)) | F5: =IF(A5=""," ",B5*VLOOKUP(A5,'18.11-07.12.2024'!A:H,7,FALSE)) | G5: =IF(A5=""," ",B5*VLOOKUP(A5,'18.11-07.12.2024'!A:H,8,FALSE))
C6: =IF(A6=""," ",VLOOKUP(A6,'18.11-07.12.2024'!A:H,2,FALSE)) | D6: =IF(A6=""," ",VLOOKUP(A6,'18.11-07.12.2024'!A:H,5,FALSE)) | E6: =IF(A6=""," ",B6*VLOOKUP(A6,'18.11-07.12.2024'!A:H,6,FALSE)) | F6: =IF(A6=""," ",B6*VLOOKUP(A6,'18.11-07.12.2024'!A:H,7,FALSE)) | G6: =IF(A6=""," ",B6*VLOOKUP(A6,'18.11-07.12.2024'!A:H,8,FALSE))
C7: =IF(A7=""," ",VLOOKUP(A7,'18.11-07.12.2024'!A:H,2,FALSE)) | D7: =IF(A7=""," ",VLOOKUP(A7,'18.11-07.12.2024'!A:H,5,FALSE)) | E7: =IF(A7=""," ",B7*VLOOKUP(A7,'18.11-07.12.2024'!A:H,6,FALSE)) | F7: =IF(A7=""," ",B7*VLOOKUP(A7,'18.11-07.12.2024'!A:H,7,FALSE)) | G7: =IF(A7=""," ",B7*VLOOKUP(A7,'18.11-07.12.2024'!A:H,8,FALSE))
C8: =IF(A8=""," ",VLOOKUP(A8,'18.11-07.12.2024'!A:H,2,FALSE)) | D8: =IF(A8=""," ",VLOOKUP(A8,'18.11-07.12.2024'!A:H,5,FALSE)) | E8: =IF(A8=""," ",B8*VLOOKUP(A8,'18.11-07.12.2024'!A:H,6,FALSE)) | F8: =IF(A8=""," ",B8*VLOOKUP(A8,'18.11-07.12.2024'!A:H,7,FALSE)) | G8: =IF(A8=""," ",B8*VLOOKUP(A8,'18.11-07.12.2024'!A:H,8,FALSE))
C9: =IF(A9=""," ",VLOOKUP(A9,'18.11-07.12.2024'!A:H,2,FALSE)) | D9: =IF(A9=""," ",VLOOKUP(A9,'18.11-07.12.2024'!A:H,5,FALSE)) | E9: =IF(A9=""," ",B9*VLOOKUP(A9,'18.11-07.12.2024'!A:H,6,FALSE)) | F9: =IF(A9=""," ",B9*VLOOKUP(A9,'18.11-07.12.2024'!A:H,7,FALSE)) | G9: =IF(A9=""," ",B9*VLOOKUP(A9,'18.11-07.12.2024'!A:H,8,FALSE))
C10: =IF(A10=""," ",VLOOKUP(A10,'18.11-07.12.2024'!A:H,2,FALSE)) | D10: =IF(A10=""," ",VLOOKUP(A10,'18.11-07.12.2024'!A:H,5,FALSE)) | E10: =IF(A10=""," ",B10*VLOOKUP(A10,'18.11-07.12.2024'!A:H,6,FALSE)) | F10: =IF(A10=""," ",B10*VLOOKUP(A10,'18.11-07.12.2024'!A:H,7,FALSE)) | G10: =IF(A10=""," ",B10*VLOOKUP(A10,'18.11-07.12.2024'!A:H,8,FALSE))
C11: =IF(A11=""," ",VLOOKUP(A11,'18.11-07.12.2024'!A:H,2,FALSE)) | D11: =IF(A11=""," ",VLOOKUP(A11,'18.11-07.12.2024'!A:H,5,FALSE)) | E11: =IF(A11=""," ",B11*VLOOKUP(A11,'18.11-07.12.2024'!A:H,6,FALSE)) | F11: =IF(A11=""," ",B11*VLOOKUP(A11,'18.11-07.12.2024'!A:H,7,FALSE)) | G11: =IF(A11=""," ",B11*VLOOKUP(A11,'18.11-07.12.2024'!A:H,8,FALSE))
C12: =IF(A12=""," ",VLOOKUP(A12,'18.11-07.12.2024'!A:H,2,FALSE)) | D12: =IF(A12=""," ",VLOOKUP(A12,'18.11-07.12.2024'!A:H,5,FALSE)) | E12: =IF(A12=""," ",B12*VLOOKUP(A12,'18.11-07.12.2024'!A:H,6,FALSE)) | F12: =IF(A12=""," ",B12*VLOOKUP(A12,'18.11-07.12.2024'!A:H,7,FALSE)) | G12: =IF(A12=""," ",B12*VLOOKUP(A12,'18.11-07.12.2024'!A:H,8,FALSE))
C13: =IF(A13=""," ",VLOOKUP(A13,'18.11-07.12.2024'!A:H,2,FALSE)) | D13: =IF(A13=""," ",VLOOKUP(A13,'18.11-07.12.2024'!A:H,5,FALSE)) | E13: =IF(A13=""," ",B13*VLOOKUP(A13,'18.11-07.12.2024'!A:H,6,FALSE)) | F13: =IF(A13=""," ",B13*VLOOKUP(A13,'18.11-07.12.2024'!A:H,7,FALSE)) | G13: =IF(A13=""," ",B13*VLOOKUP(A13,'18.11-07.12.2024'!A:H,8,FALSE))
C14: =IF(A14=""," ",VLOOKUP(A14,'18.11-07.12.2024'!A:H,2,FALSE)) | D14: =IF(A14=""," ",VLOOKUP(A14,'18.11-07.12.2024'!A:H,5,FALSE)) | E14: =IF(A14=""," ",B14*VLOOKUP(A14,'18.11-07.12.2024'!A:H,6,FALSE)) | F14: =IF(A14=""," ",B14*VLOOKUP(A14,'18.11-07.12.2024'!A:H,7,FALSE)) | G14: =IF(A14=""," ",B14*VLOOKUP(A14,'18.11-07.12.2024'!A:H,8,FALSE))
... C876: =IF(A876=""," ",VLOOKUP(A876,'18.11-07.12.2024'!A:H,2,FALSE)) | D876: =IF(A876=""," ",VLOOKUP(A876,'18.11-07.12.2024'!A:H,5,FALSE)) | E876: =IF(A876=""," ",B876*VLOOKUP(A876,'18.11-07.12.2024'!A:H,6,FALSE)) | F876: =IF(A876=""," ",B876*VLOOKUP(A876,'18.11-07.12.2024'!A:H,7,FALSE)) | G876: =IF(A876=""," ",B876*VLOOKUP(A876,'18.11-07.12.2024'!A:H,8,FALSE))

Sheet 18.11-07.12.2024
A1: КОД | B1: СКИДКА | C1: СТР. | D1: АКЦИЯ | E1: НАИМЕНОВАНИЕ | F1: ББ | G1: ОП | H1: ПЦ
A2: НОВИНКИ
A3: 46055 | C3: 52 | E3: МУЖСКИЕ ДУХИ GIORDANI GOLD ESSENZA ELIXIR (ПРОБНИК) | F3: 0 | G3: 0 | H3: 35
A4: 46069 | B4: 0.50083333 | C4: 23 | E4: НАБОР СПЕЦИАЛЬНЫХ СМЯГЧАЮЩИХ СРЕДСТВ | F4: 6 | G4: 384 | H4: 599
A5: 46607 | B5: 0.4568 | C5: 5 | E5: КРЕМОВАЯ ГУБНАЯ ПОМАДА С БЛЕСТЯЩИМ СТЕРЖНЕМ THE ONE - НЕПОВТОРИМЫЙ НЮД | F5: 7 | G5: 436 | H5: 679
A6: 46608 | B6: 0.4568 | C6: 5 | E6: - ВПЕЧАТЛЯЮЩИЙ РОЗОВЫЙ | F6: 7 | G6: 436 | H6: 679
A7: 46609 | B7: 0.4568 | C7: 5 | E7: - АЛЫЙ РУБИН | F7: 7 | G7: 436 | H7: 679
A8: 46642 | B8: 0.4408 | C8: 21 | E8: ЖИДКОЕ МЫЛО ДЛЯ РУК И ТЕЛА С ЛИМОНОМ И ВЕРБЕНОЙ ESSENSE & CO. | F8: 7 | G8: 449 | H8: 699
A9: 46643 | B9: 0.450625 | C9: 21 | E9: ЛОСЬОН ДЛЯ РУК И ТЕЛА С ЛИМОНОМ И ВЕРБЕНОЙ ESSENSE & CO. | F9: 9 | G9: 564 | H9: 879
A10: 46705 | B10: 0.40181818 | C10: 11 | E10: ГЕЛЬ-ЛАК ДЛЯ НОГТЕЙ THE ONE - ГЛАМУРНЫЙ ЗЕЛЁНЫЙ | F10: 3 | G10: 211 | H10: 329
A11: 46706 | B11: 0.40181818 | C11: 11 | E11: - ЭФФЕКТНЫЙ РОЗОВЫЙ | F11: 3 | G11: 211 | H11: 329
A12: 46707 | B12: 0.40181818 | C12: 11 | E12: - ВЛАСТНЫЙ КРАСНЫЙ | F12: 3 | G12: 211 | H12: 329
A13: 46708 | B13: 0.40181818 | C13: 11 | E13: - ЗАГАДОЧНЫЙ БРОНЗОВЫЙ | F13: 3 | G13: 211 | H13: 329
A14: 46731 | B14: 0.44428571 | C14: 21 | E14: ЖИДКОЕ МЫЛО ДЛЯ РУК И ТЕЛА С ЛИМОНОМ И ВЕРБЕНОЙ ESSENSE & CO. (РЕФИЛ) | F14: 4 | G14: 249 | H14: 389
A15: 47012 | B15: 0.34869565 | C15: 47 | E15: ПАРФЮМИРОВАННЫЙ КРЕМ ДЛЯ ТЕЛА AMBER ELIXIR | F15: 7 | G15: 480 | H15: 749
... A24: 47543 | B24: 0.44814815 | C24: 144 | E24: МОЧАЛКА ДЛЯ ДУША | F24: 1 | G24: 48 | H24: 149
A25: 47550 | C25: 13 | E25: НАБОР КИСТЕЙ ДЛЯ МАКИЯЖА | F25: 16 | G25: 513 | H25: 1600
A26: 47551 | B26: 0.39508197 | C26: 10 | E26: СИЛИКОНОВЫЙ СПОНЖ ДЛЯ МАКИЯЖА | F26: 4 | G26: 118 | H26: 369
A27: 47552 | B27: 0.3604 | C27: 10 | E27: КОСМЕТИЧКА | F27: 16 | G27: 513 | H27: 1599
A28: 47554 | B28: 0.40810811 | C28: 10 | E28: НАБОР ПИЛОК ДЛЯ НОГТЕЙ | F28: 2 | G28: 70 | H28: 219
A29: 47628 | C29: 15 | E29: ЧАСЫ С ИЗУМРУДНЫМ ЦИФЕРБЛАТОМ | F29: 30 | G29: 962 | H29: 2999
A30: 47630 | C30: 16 | E30: СЕРЬГИ-ГВОЗДИКИ С ИЗУМРУДНЫМИ КРИСТАЛЛАМИ | F30: 13 | G30: 417 | H30: 1299
A31: 47631 | C31: 16 | E31: КОЛЬЕ-ЦЕПОЧКА С ИЗУМРУДНЫМИ КРИСТАЛЛАМИ | F31: 16 | G31: 513 | H31: 1599
A32: 47650 | C32: 14 | E32: СУМКА С БАНТОМ НА ЦЕПОЧКЕ | F32: 25 | G32: 802 | H32: 2499
A33: 47652 | C33: 14 | E33: НАБОР ЗАКОЛОК ДЛЯ ВОЛОС | F33: 9 | G33: 288 | H33: 899
A34: 47654 | C34: 14 | E34: ОБОДОК ДЛЯ ВОЛОС СО СТРАЗАМИ | F34: 10 | G34: 321 | H34: 999
A35: 47662 | C35: 17 | E35: НАБОР УКРАШЕНИЙ С НАТУРАЛЬНОЙ ШПИНЕЛЬЮ | F35: 15 | G35: 481 | H35: 1499
A36: 150838 | B36: 0.44862069 | C36: 29 | E36: НОЧНАЯ МАСКА ДЛЯ ИНТЕНСИВНОГО ВОССТАНОВЛЕНИЯ КОЖИ NOVAGE+. ПРАЗДНИЧНЫЙ ВЫПУСК | F36: 16 | G36: 1026 | H36: 1599
A37: КАТАЛОГ
E38: WELLOSOPHY
A39: 29699 | B39: 0.2005 | C39: 97 | E39: КОМПЛЕКС «МУЛЬТИВИТАМИНЫ И МИНЕРАЛЫ» ДЛЯ ДЕТЕЙ | F39: 16 | G39: 1026 | H39: 1599
A40: 29695 | C40: 94 | E40: СУП «НЭЧУРАЛ БАЛАНС» - СПАРЖА | F40: 52 | G40: 3208 | H40: 5000
A41: 37285 | C41: 95 | E41: СУХАЯ СМЕСЬ ДЛЯ КОКТЕЙЛЯ «НЭЧУРАЛ БАЛАНС» - КЛУБНИЧНЫЙ ВКУС | F41: 52 | G41: 3208 | H41: 5000
A42: 37289 | C42: 95 | E42: СУХАЯ СМЕСЬ ДЛЯ КОКТЕЙЛЯ «НЭЧУРАЛ БАЛАНС» - ШОКОЛАДНЫЙ ВКУС | F42: 52 | G42: 3208 | H42: 5000
A43: 37290 | C43: 95 | E43: СУХАЯ СМЕСЬ ДЛЯ КОКТЕЙЛЯ «НЭЧУРАЛ БАЛАНС» - ВАНИЛЬНЫЙ ВКУС | F43: 52 | G43: 3208 | H43: 5000
A44: 37293 | C44: 94 | E44: ПРОТЕИНОВЫЙ КОМПЛЕКС | F44: 52 | G44: 3208 | H44: 5000
A45: 38556 | C45: 90 | E45: КОМПЛЕКС «ОМЕГА-3» | F45: 24 | G45: 1475 | H45: 2300
A46: 38557 | B46: 0.39321429 | C46: 89 | E46: КОМПЛЕКС «АСТАКСАНТИН И ЭКСТРАКТ ЧЕРНИКИ» | F46: 18 | G46: 1090 | H46: 1699
A47: 38558 | C47: 91 | E47: КОМПЛЕКС «МУЛЬТИВИТАМИНЫ И МИНЕРАЛЫ» ДЛЯ МУЖЧИН | F47: 29 | G47: 1797 | H47: 2800
A48: 38559 | C48: 91 | E48: КОМПЛЕКС «МУЛЬТИВИТАМИНЫ И МИНЕРАЛЫ» ДЛЯ ЖЕНЩИН | F48: 29 | G48: 1797 | H48: 2800
...
